/usr/local/lib/python3.7/dist-packages/trio/_core/_multierror.py:472: RuntimeWarning: You seem to already have a custom sys.excepthook handler installed. I'll skip installing Trio's custom handler, but this means MultiErrors will not show full tracebacks.
  category=RuntimeWarning
Traceback (most recent call last):
  File "../example.py", line 22, in <module>
    server = AsyncAPY(config='server.conf')
  File "/root/AsyncAPY/AsyncAPY/base.py", line 115, in __init__
    self.load_config()
  File "/root/AsyncAPY/AsyncAPY/base.py", line 130, in load_config
    parser.read_file(open(self.config, "r"))
FileNotFoundError: [Errno 2] No such file or directory: 'server.conf'
